Workbook

Sheet Start here
A1: Poster run: all 4 brands in one go
A2: Waypoint, Waypoint Apps, Staffkin and Keegix stop lists merged: one row per place, so one visit covers every brand that goes there.
A4: Outing | B4: Stops | C4: Done | D4: Priority 1
A5: 1 · Weekday daytime (half day off or lunch hours) | B5: =COUNTIF('Master route'!$B$5:$B$142,"1") -> 28 | C5: =COUNTIFS('Master route'!$B$5:$B$142,"1",'Master route'!$P$5:$P$142,"Y") -> 0 | D5: =COUNTIFS('Master route'!$B$5:$B$142,"1",'Master route'!$G$5:$G$142,1) -> 17
A6: 2 · Saturday: Wolfville & Grand Pré (start 8:30 at the market) | B6: =COUNTIF('Master route'!$B$5:$B$142,"2") -> 31 | C6: =COUNTIFS('Master route'!$B$5:$B$142,"2",'Master route'!$P$5:$P$142,"Y") -> 0 | D6: =COUNTIFS('Master route'!$B$5:$B$142,"2",'Master route'!$G$5:$G$142,1) -> 14
A7: 3 · Kentville & Coldbrook (weekend, or a weeknight before 6) | B7: =COUNTIF('Master route'!$B$5:$B$142,"3") -> 21 | C7: =COUNTIFS('Master route'!$B$5:$B$142,"3",'Master route'!$P$5:$P$142,"Y") -> 0 | D7: =COUNTIFS('Master route'!$B$5:$B$142,"3",'Master route'!$G$5:$G$142,1) -> 15
A8: 4 · New Minas (any evening or weekend) | B8: =COUNTIF('Master route'!$B$5:$B$142,"4") -> 23 | C8: =COUNTIFS('Master route'!$B$5:$B$142,"4",'Master route'!$P$5:$P$142,"Y") -> 0 | D8: =COUNTIFS('Master route'!$B$5:$B$142,"4",'Master route'!$G$5:$G$142,1) -> 12
A9: 5 · West Saturday (Annapolis Royal → Canning) | B9: =COUNTIF('Master route'!$B$5:$B$142,"5") -> 21 | C9: =COUNTIFS('Master route'!$B$5:$B$142,"5",'Master route'!$P$5:$P$142,"Y") -> 0 | D9: =COUNTIFS('Master route'!$B$5:$B$142,"5",'Master route'!$G$5:$G$142,1) -> 0
A10: 5b · Hantsport & Windsor (add-on, low priority) | B10: =COUNTIF('Master route'!$B$5:$B$142,"5b") -> 3 | C10: =COUNTIFS('Master route'!$B$5:$B$142,"5b",'Master route'!$P$5:$P$142,"Y") -> 0 | D10: =COUNTIFS('Master route'!$B$5:$B$142,"5b",'Master route'!$G$5:$G$142,1) -> 0
A11: 6 · Seasonal / special days | B11: =COUNTIF('Master route'!$B$5:$B$142,"6") -> 4 | C11: =COUNTIFS('Master route'!$B$5:$B$142,"6",'Master route'!$P$5:$P$142,"Y") -> 0 | D11: =COUNTIFS('Master route'!$B$5:$B$142,"6",'Master route'!$G$5:$G$142,1) -> 2
A12: All in-person stops | B12: =SUM(B5:B11) -> 131 | C12: =SUM(C5:C11) -> 0 | D12: =SUM(D5:D11) -> 60
A13: Mail from home (Keegix letters + Staffkin postcards) | B13: =COUNTA('Mail from home'!C5:C100) -> 34 | C13: =COUNTA('Mail from home'!J5:J100) -> 0
A15: How to use
A16: • Print everything once (see poster-run-print-list.xlsx), then work outing by outing on the Master route tab. Filter column B to one outing.
A17: • Each row says what to leave per brand. Brands column: W = Waypoint, A = Waypoint Apps, S = Staffkin, K = Keegix.
A18: • Keegix pieces are numbered per spot (cards C##, flyer L##): grab the right page for each stop so scans can be traced.
A19: • Restaurants (Staffkin): go 2–4 pm, never at lunch or dinner rush. Offices: weekdays only.
A20: • Ask first everywhere. Boards get cleared every 2–4 weeks, so re-post in the first week of each month.
A22: Decisions made for you (change them if you like)
A23: • Waypoint flyer: design B "Still doing it by hand?" at trades counters, design A at the coworking space.
A24: • Apps poster: design B "Selling at markets?" at farm and farmers' markets, design A (tear-offs) everywhere else.
A25: • Keegix: card option A (yellow key cards) + flyer option 4 (Airbnb house rules) until Nov 20, then flyer option 3 (tear-off).
A26: • Keegix spots had no priority in the source list, so Keegix-only stops are set to priority 2.
A27: • Outings are grouped by opening hours from the source lists (Google Maps, 21 Oct 2026). Check hours before a long drive.
A29: Sources: poster-run/waypoint-flyer-run.xlsx, staffkin-flyer-stops.xlsx, keegix/2-lists/keegix-dropoff-spots-valley.xlsx, keegix/2-lists/mail-30.csv (Social-posts repo, 21 Oct 2026).

Sheet Master route
A1: Poster run: master route (all 4 brands)
A2: One row per place. Each brand column says what to leave there; blank = nothing for that brand. Grouped into outings by when places are open. Fill the yellow Done column with Y.
M3: Done: | N3: =COUNTIF(P5:P142,"Y")&" of "&COUNT(A5:A142) -> 0 of 131
A4: # | B4: Outing | C4: Town | D4: Place | E4: Address (paste into Maps) | F4: Hours (check first) | G4: Priority | H4: Brands | I4: Waypoint: leave | J4: Apps: leave | K4: Staffkin: leave | L4: Keegix: leave (codes) | M4: What to say | N4: Notes | O4: Map | P4: Done (Y)
A5: 1 · Weekday daytime (half day off or lunch hours)
A6: 1 | B6: 1 | C6: Kentville | D6: Computerized Business Solutions | E6: Suite 500, 946 Park St, Kentville, NS B4N 3V7 | G6: 1 | H6: S | K6: Counter card (A) in person | M6: Staffkin: "I saw you're hiring a receptionist. Staffkin does the job ad, interview questions and reference checks. First job is free." | N6: Hiring: Receptionist. | O6: Open
A7: 2 | B7: 1 | C7: Kentville | D7: Taylor MacLellan Cochrane | E7: 50 Bridge St, Kentville, NS B4N 2E4 | G7: 1 | H7: S | K7: Counter card (A) in person | M7: Staffkin: "I saw you're hiring a paralegal. Staffkin does the job ad, interview questions and reference checks. First job is free." | N7: Hiring: Paralegal. | O7: Open
A8: 3 | B8: 1 | C8: Kentville | D8: White Rock Mechanical | E8: 51 Chipman Dr #1, Kentville, NS B4N 3V7 | F8: 8:30 AM – 4:30 PM | G8: 2 | H8: S | K8: Pocket card (D) or counter card (A) | M8: Staffkin: Leave with the front desk for the owner. Best time: Weekday 10 am–3 pm. | O8: Open
A9: 4 | B9: 1 | C9: Kentville | D9: White Rock Electrical Services Ltd | E9: 87 Chipman Dr #1, Kentville, NS B4N 3V7 | F9: 8:30 AM – 4:30 PM | G9: 2 | H9: S | K9: Pocket card (D) or counter card (A) | M9: Staffkin: Leave with the front desk for the owner. Best time: Weekday 10 am–3 pm. | O9: Open
A10: 5 | B10: 1 | C10: Kentville | D10: Kent & Duffett Chartered Professional Accountants | E10: 46 Chipman Dr Unit 1, Kentville, NS B4N 3V7 | F10: Weekdays | G10: 1 | H10: W S | I10: counter cards (C) (small stack) | K10: 3 counter cards (A) | M10: Waypoint/Apps: Cards for clients still doing invoices by hand. Staffkin: Ask who handles small-business clients. Mention the partner program (they earn on referrals). Best time: Weekday mid-morning. | N10: Hours not listed; check before going. | O10: Open
A11: 6 | B11: 1 | C11: Kentville | D11: Credit Union Rec Complex | E11: 38 Gary Pearl Dr, Kentville, NS | F11: Weekdays | G11: 3 | H11: A | J11: poster A tear-off "Digitize your whole business" on board | M11: Waypoint/Apps: Ask at the front desk. | O11: Open
A12: 7 | B12: 1 | C12: Kentville | D12: Troy Bennett's Auto Repair & Service | E12: 28 lyons drive, Kentville, NS B4N 3V7 | F12: 8:00 AM – 5:00 PM | G12: 2 | H12: S | K12: Pocket card (D) | M12: Staffkin: Leave a card for the owner or service manager. Best time: Weekday 10 am–3 pm. | O12: Open
A13: 8 | B13: 1 | C13: Kentville | D13: Kentville Recreation Centre | E13: 348 Main St, Kentville, NS | F13: Mon–Fri 8:30–4:30 | G13: 3 | H13: A | J13: poster A tear-off "Digitize your whole business" on board | M13: Waypoint/Apps: Ask at the front desk. | O13: Open
A14: 9 | B14: 1 | C14: Kentville | D14: Bage CPA | E14: 402 Main St, Kentville, NS B4N 1K8 | F14: 10:00 AM – 4:00 PM | G14: 1 | H14: S | K14: 3 counter cards (A) | M14: Staffkin: Ask who handles small-business clients. Mention the partner program (they earn on referrals). Best time: Weekday mid-morning. | O14: Open
A15: 10 | B15: 1 | C15: Kentville | D15: Mister Printer | E15: 409 Main St, Kentville, NS B4N 2E2 | F15: 8:30 AM – 5:00 PM | G15: 3 | H15: S | K15: Board poster (C) | M15: Staffkin: Ask if they have a community or business board. Best time: Opening hours. | O15: Open
A16: 11 | B16: 1 | C16: Kentville | D16: CBDC Hants-Kings | E16: 448 Main St, Kentville, NS B4N 1R5 | F16: Mon–Fri 8:30–4:30 | G16: 1 | H16: W A S | I16: counter cards (C) (small stack) | J16: take-one cards (C) (small stack) | K16: 3 counter cards (A) | M16: Waypoint/Apps: They lend to and advise new owners. Ask to leave cards for clients and if you can drop off more later. Staffkin: Ask to put the poster on the board and a few cards in the brochure rack for members. Best time: Weekday 9 am–4 pm. | N16: Lends to small businesses; their clients are your customers. | O16: Open
A17: 12 | B17: 1 | C17: Kentville | D17: Valley Regional Enterprise Network (Valley REN) | E17: 448 Main St, Kentville, NS B4N 1R5 | F17: Mon–Fri 8:30–4:30 | G17: 1 | H17: W A S | I17: counter cards (C) | J17: take-one cards (C) | K17: 3 counter cards (A) | M17: Waypoint/Apps: Same building as CBDC. Ask about their business newsletter and leaving cards. Staffkin: Ask to put the poster on the board and a few cards in the brochure rack for members. Best time: Weekday 9 am–4 pm. | O17: Open
A18: 13 | B18: 1 | C18: Kentville | D18: Annapolis Valley Chamber of Commerce | E18: 448 Main St, Kentville, NS B4N 1R5 | F18: Mon–Fri 8:30–4 | G18: 1 | H18: W A S | I18: counter cards (C) | J18: take-one cards (C) | K18: Board poster (C) + 5 counter cards (A) | M18: Waypoint/Apps: Ask about the members' board, the newsletter, and leaving cards. Staffkin: Ask to put the poster on the board and a few cards in the brochure rack for members. Best time: Weekday 9 am–4 pm. | N18: Same building as CBDC, Valley REN and Valley Business Hub: one stop, four offices. | O18: Open
A19: 14 | B19: 1 | C19: Kentville | D19: Valley Business Hub | E19: 448 Main St, Kentville, NS B4N 1R5 | F19: 8:30 AM – 4:30 PM | G19: 1 | H19: S | K19: 3 counter cards (A) | M19: Staffkin: Ask to put the poster on the board and a few cards in the brochure rack for members. Best time: Weekday 9 am–4 pm. | O19: Open
A20: 15 | B20: 1 | C20: Kentville | D20: mbf Chartered Professional Accountants | E20: 464 Main St, Kentville, NS B4N 1K8 | F20: Mon–Fri 8:30–4:30 | G20: 1 | H20: W S | I20: counter cards (C) (small stack) | K20: 3 counter cards (A) | M20: Waypoint/Apps: Ask if you can leave a few cards for clients who are still on paper. Don't pitch the apps here. Staffkin: Ask who handles small-business clients. Mention the partner program (they earn on referrals). Best time: Weekday mid-morning. | O20: Open
A21: 16 | B21: 1 | C21: Kentville | D21: Greg Dodge's Auto Repair | E21: 81 New Canaan Rd, Kentville, NS B4N 4K1 | F21: 8:00 AM – 5:00 PM | G21: 2 | H21: S | K21: Pocket card (D) | M21: Staffkin: Leave a card for the owner or service manager. Best time: Weekday 10 am–3 pm. | O21: Open
A22: 17 | B22: 1 | C22: Kentville | D22: Ron Martin's Plumbing and Heating 2022 Ltd | E22: 913 Park St, Kentville, NS B4N 5H3 | F22: 8:00 AM – 4:30 PM | G22: 2 | H22: S | K22: Pocket card (D) or counter card (A) | M22: Staffkin: Leave with the front desk for the owner. Best time: Weekday 10 am–3 pm. | O22: Open
A23: 18 | B23: 1 | C23: Kentville | D23: Van Meekeren Farms Ltd. | E23: 237 Thorpe Rd, Kentville, NS B4N 3V7 | G23: 1 | H23: S | K23: Counter card (A) in person | M23: Staffkin: "I saw you're hiring a fruit packer. Staffkin does the job ad, interview questions and reference checks. First job is free." | N23: Hiring: Fruit packer. | O23: Open
A24: 19 | B24: 1 | C24: Kentville | D24: Infinite Solutions Bookkeeping & Accounting | E24: 25 Webster Ct, Kentville, NS B4N 1H3 | F24: Mon–Fri 8:30–4:30 | G24: 1 | H24: W S | I24: counter cards (C) (small stack) | K24: 3 counter cards (A) | M24: Waypoint/Apps: Same ask as accountants: cards for clients drowning in paperwork. Staffkin: Ask who handles small-business clients. Mention the partner program (they earn on referrals). Best time: Weekday mid-morning. | N24: Best partner fit: bookkeepers see hiring pain first. | O24: Open
A25: 20 | B25: 1 | C25: Kentville | D25: Doane Grant Thornton LLP | E25: 15 Webster St, Kentville, NS B4N 1H4 | F25: 9:00 AM – 5:00 PM | G25: 1 | H25: S | K25: 3 counter cards (A) | M25: Staffkin: Ask who handles small-business clients. Mention the partner program (they earn on referrals). Best time: Weekday mid-morning. | N25: Larger firm; lower odds. | O25: Open
A26: 21 | B26: 1 | C26: Kentville | D26: The Space and Company (coworking) | E26: 10 Webster St #210, Kentville, NS | F26: Weekdays | G26: 1 | H26: W A | I26: flyer A "I make the software fit" on board | J26: take-one cards (C) (small stack) | M26: Waypoint/Apps: Freelancers and small owners work here. Ask to leave cards in the common area. | O26: Open
A27: 22 | B27: 1 | C27: Coldbrook | D27: Stoddart's Automotive Service Ltd. | E27: 6961 Nova Scotia Trunk 1, Coldbrook, NS B4R 1C5 | F27: 8:00 AM – 5:00 PM | G27: 2 | H27: S | K27: Pocket card (D) | M27: Staffkin: Leave a card for the owner or service manager. Best time: Weekday 10 am–3 pm. | O27: Open
A28: 23 | B28: 1 | C28: New Minas | D28: Repracorp Design and Print | E28: 8927 Commercial St, New Minas, NS | F28: Mon–Fri 8–5 | G28: 2 | H28: W S | I28: counter cards (C) (small stack) | K28: Board poster (C) | M28: Waypoint/Apps: Business print customers. Ask at the front. Staffkin: Ask if they have a community or business board. Best time: Opening hours. | O28: Open
A29: 24 | B29: 1 | C29: New Minas | D29: Panda Print | E29: 9146 Commercial St, New Minas, NS | F29: Mon–Fri 9–5 | G29: 1 | H29: W A S | I29: counter cards (C) | J29: take-one cards (C) | K29: Board poster (C) | M29: Waypoint/Apps: Owners print signs and cards here. Ask to leave cards on the counter. Staffkin: Ask if they have a community or business board. Best time: Opening hours. | O29: Open
A30: 25 | B30: 1 | C30: New Minas | D30: Valley Credit Union | E30: 9237 Commercial St, New Minas, NS | F30: Mon–Fri 10–4 | G30: 2 | H30: W | I30: counter cards (C) (small stack) | M30: Waypoint/Apps: Business banking. Ask whether they have a board or take cards. | O30: Open
A31: 26 | B31: 1 | C31: New Minas | D31: Fleetworx Inc. | E31: 64 Minas Warehouse Rd, New Minas, NS B4N 5G3 | F31: Mon–Fri 8–5 | G31: 1 | H31: W S | I31: counter cards (C) (small stack) | K31: Counter card (A) in person | M31: Waypoint/Apps: Fleet owners. Cards at the counter. Staffkin: "I saw you're hiring a refrigeration mechanic. Staffkin does the job ad, interview questions and reference checks. First job is free." | N31: Hiring: Refrigeration mechanic. | O31: Open
A32: 27 | B32: 1 | C32: New Minas | D32: Valley Power Products (rentals) | E32: 9 Nova Dr, New Minas, NS B4N 3G7 | F32: Mon–Fri 7:30–5 | G32: 1 | H32: W | I32: flyer B "Still doing it by hand?" on board + counter cards (C) (small stack) | M32: Waypoint/Apps: Contractors rent here. Ask about a board or cards at the counter. | O32: Open
A33: 28 | B33: 1 | C33: Greenwich | D33: TNT Tool Rental & Safety | E33: 9776 Hwy 1, Greenwich, NS B4P 0A7 | F33: Mon–Fri 7:30–5 | G33: 1 | H33: W | I33: flyer B "Still doing it by hand?" on board + counter cards (C) (small stack) | M33: Waypoint/Apps: Contractors rent here. Ask about a board or cards at the counter. | O33: Open
A34: 2 · Saturday: Wolfville & Grand Pré (start 8:30 at the market)
A35: 29 | B35: 2 | C35: Greenwich | D35: Noggins Corner Farm Market | E35: 10009 Hwy 1, Greenwich, NS | F35: Daily 8–8 | G35: 2 | H35: A | J35: poster B "Selling at markets?" on board | M35: Waypoint/Apps: Local producers sell here. Ask about the board. | O35: Open
A36: 30 | B36: 2 | C36: Greenwich | D36: Hennigar's Farm Market | E36: 10272, Nova Scotia Trunk 1, Wolfville, NS B4P 2R2 | F36: Mon–Fri 8am–7pm, Sat 8am–7pm, Sun 8am–7pm | G36: 2 | H36: A K | J36: poster B "Selling at markets?" on board | L36: Key cards at the till + flyer (cards C28, flyer L28) | M36: Waypoint/Apps: Local producers sell here. Ask about the board. Keegix: Very busy (1,600+ reviews) | O36: Open
A37: 31 | B37: 2 | C37: Wolfville | D37: Rafuse Home Hardware Building Centre | E37: 180 Dykeland St, Wolfville, NS B4P 1A2 | F37: Mon 7:30am–5:30pm, Tue 7:30am–5:30pm, Wed 7:30am–5:30pm, Thu 7:30am–5:30pm, Fri 7:30am–6pm, Sat 8am–5pm, Sun 10am–5pm | G37: 2 | H37: S K | K37: Small stack of pocket cards (D) | L37: Key cards at the till (ask) (cards C35, flyer L35) | M37: Staffkin: Ask if you can leave a few cards at the contractor desk. Best time: Mid-morning, after the 7–9 am contractor rush. Keegix: Wolfville | O37: Open
A38: 32 | B38: 2 | C38: Wolfville | D38: Jeju Restaurant | E38: 8 Elm Ave, Wolfville, NS B4P 1Z9 | G38: 1 | H38: S | K38: Counter card (A) in person | M38: Staffkin: "I saw you're hiring a chef. Staffkin does the job ad, interview questions and reference checks. First job is free." | N38: Hiring: Chef. | O38: Open
A39: 33 | B39: 2 | C39: Wolfville | D39: Troy Restaurant & Grill | E39: 12D Elm Ave, Wolfville, NS B4P 1Z9 | F39: 11:00 AM – 8:00 PM | G39: 1 | H39: S | K39: Counter card (A) | M39: Staffkin: Ask for the owner or manager. "If you're ever hiring, this does the ad, interviews and reference checks. First job is free." Best time: 2–4 pm, never lunch rush. | O39: Open
A40: 34 | B40: 2 | C40: Wolfville | D40: Realm Boutique | E40: 12 Elm Ave, Wolfville, NS B4P 1Z9 | F40: 10:00 AM – 6:00 PM | G40: 3 | H40: S | K40: Pocket card (D) | M40: Staffkin: Leave a card for the owner. Best time: Weekday, quiet times. | O40: Open
...

Sheet Mail from home
A1: Mail from home (no driving)
A2: Keegix: 30 window-envelope letters with numbered key cards (codes M01–M30). Staffkin: reference-check postcards (B) to businesses hiring with no street address posted. Fill the yellow column.
A4: Brand | B4: Code | C4: Place | D4: Type | E4: Address | F4: City | G4: Postcode | H4: Region | I4: What to send | J4: Mailed on
A5: Keegix | B5: M01 | C5: Broadwater Inn & Cottages | D5: inn | E5: 975 NS-205 | F5: Baddeck | G5: B0E 1B0 | H5: Cape Breton | I5: Letter + key card M01 taped on, return label, stamp
A6: Keegix | B6: M02 | C6: Chanterelle Inn & Cottages | D6: inn | E6: 48678 Cabot Trail | F6: Baddeck | G6: B0E 1B0 | H6: Cape Breton | I6: Letter + key card M02 taped on, return label, stamp
A7: Keegix | B7: M03 | C7: McIntyre's Cottages & Cameron House | D7: cottages | E7: 8908 NS-105 | F7: Baddeck | G7: B0E 1B0 | H7: Cape Breton | I7: Letter + key card M03 taped on, return label, stamp
A8: Keegix | B8: M04 | C8: L'Auberge Doucet Inn | D8: inn | E8: 14758 Cabot Trail | F8: Chéticamp | G8: B0E 1H0 | H8: Cape Breton | I8: Letter + key card M04 taped on, return label, stamp
A9: Keegix | B9: M05 | C9: Pilot Whale Chalets | D9: cottages | E9: 15775 Cabot Trail | F9: Chéticamp | G9: B0E 1H0 | H9: Cape Breton | I9: Letter + key card M05 taped on, return label, stamp
A10: Keegix | B10: M06 | C10: Silver Lining Inn | D10: inn | E10: 15356 Cabot Trail | F10: Chéticamp | G10: B0E 1H0 | H10: Cape Breton | I10: Letter + key card M06 taped on, return label, stamp
A11: Keegix | B11: M07 | C11: Maple Ridge Cabins | D11: cottages | E11: 27340 Cabot Trail | F11: Dingwall | G11: B0C 1G0 | H11: Cape Breton | I11: Letter + key card M07 taped on, return label, stamp
A12: Keegix | B12: M08 | C12: Rocky Bay Cottages | D12: cottages | E12: 33 Miltons Ln | F12: Ingonish | G12: B0C 0A5 | H12: Cape Breton | I12: Letter + key card M08 taped on, return label, stamp
A13: Keegix | B13: M09 | C13: Seascape Coastal Retreat | D13: cottages | E13: 36086 Cabot Trail | F13: Ingonish | G13: B0C 1K0 | H13: Cape Breton | I13: Letter + key card M09 taped on, return label, stamp
A14: Keegix | B14: M10 | C14: Power Brook Accommodations | D14: cottages | E14: 38397 Cabot Trail | F14: Ingonish Beach | G14: B0C 1L0 | H14: Cape Breton | I14: Letter + key card M10 taped on, return label, stamp
A15: Keegix | B15: M11 | C15: Skyline Cabins | D15: cottages | E15: 37759 Cabot Trail | F15: Ingonish Beach | G15: B0C 1L0 | H15: Cape Breton | I15: Letter + key card M11 taped on, return label, stamp
A16: Keegix | B16: M12 | C16: The Island Inn | D16: B&B | E16: 37706 Cabot Trail | F16: Ingonish Beach | G16: B0C 1L0 | H16: Cape Breton | I16: Letter + key card M12 taped on, return label, stamp
... A34: Keegix | B34: M30 | C34: Tattingstone Inn | D34: inn | E34: 620 Main St | F34: Wolfville | G34: B4P 1E8 | H34: Valley | I34: Letter + key card M30 taped on, return label, stamp
A35: Staffkin | C35: Archie's Welding Inc. | D35: Welding and fabrication | E35: Address not posted: find it via the Job Bank posting, or skip | F35: New Minas | G35: B4N 3N4 | H35: Valley | I35: Postcard B ($9 reference checks). Hiring: Welding supervisor.
A36: Staffkin | C36: Jyllikleen | D36: Cleaning service | E36: Address not posted: find it via the Job Bank posting, or skip | F36: New Minas | G36: B4N 3E6 | H36: Valley | I36: Postcard B ($9 reference checks). Hiring: Cleaner.
A37: Staffkin | C37: King's Janitorial Inc. | D37: Commercial cleaning | E37: Address not posted: find it via the Job Bank posting, or skip | F37: Kentville | H37: Valley | I37: Postcard B ($9 reference checks). Hiring: Cleaner.
A38: Staffkin | C38: Eric Turner (snow removal) | D38: Snow removal contractor | E38: Address not posted: find it via the Job Bank posting, or skip | F38: Kentville | G38: B4N 4K4 | H38: Valley | I38: Postcard B ($9 reference checks). Hiring: Snow removal operator.
A40: Keegix backup batch: keegix/2-lists/mail-backup-20.csv (send after these 30). Tattingstone Inn (M30) is also on the Staffkin "hiring now" list: one letter, mention both if you visit in person.
